2025-10-18 10:57:49,678 - ERROR - Необработанное исключение: RuntimeError: 'cryptography' package is required for sha256_password or caching_sha2_password auth methods
2025-10-18 10:57:49,680 - ERROR - Трассировка стека:
Traceback (most recent call last):
  File "c:\Users\Alex_SSHOR13\Competitions_TT\main.py", line 1746, in <module>
    fir_window = StartWindow()  # Создаём объект класса ExampleApp
                 ^^^^^^^^^^^^^
  File "c:\Users\Alex_SSHOR13\Competitions_TT\main.py", line 1311, in __init__
    conn = pymysql.connect(host='localhost', user='root', password='db_pass')
           ^^^^^^^^^^^^^^^^^^^^^^^^^^^^^^^^^^^^^^^^^^^^^^^^^^^^^^^^^^^^^^^^^^
  File "C:\Users\Alex_SSHOR13\Competitions_TT\venv\Lib\site-packages\pymysql\connections.py", line 365, in __init__
    self.connect()
  File "C:\Users\Alex_SSHOR13\Competitions_TT\venv\Lib\site-packages\pymysql\connections.py", line 681, in connect
    self._request_authentication()
  File "C:\Users\Alex_SSHOR13\Competitions_TT\venv\Lib\site-packages\pymysql\connections.py", line 980, in _request_authentication
    auth_packet = _auth.caching_sha2_password_auth(self, auth_packet)
                  ^^^^^^^^^^^^^^^^^^^^^^^^^^^^^^^^^^^^^^^^^^^^^^^^^^^
  File "C:\Users\Alex_SSHOR13\Competitions_TT\venv\Lib\site-packages\pymysql\_auth.py", line 271, in caching_sha2_password_auth
    data = sha2_rsa_encrypt(conn.password, conn.salt, conn.server_public_key)
           ^^^^^^^^^^^^^^^^^^^^^^^^^^^^^^^^^^^^^^^^^^^^^^^^^^^^^^^^^^^^^^^^^^
  File "C:\Users\Alex_SSHOR13\Competitions_TT\venv\Lib\site-packages\pymysql\_auth.py", line 144, in sha2_rsa_encrypt
    raise RuntimeError(
RuntimeError: 'cryptography' package is required for sha256_password or caching_sha2_password auth methods
