2025-10-18 11:17:42,950 - ERROR - Необработанное исключение: OperationalError: (1054, "Unknown column 't2.id' in 'where clause'")
2025-10-18 11:17:42,951 - ERROR - Трассировка стека:
Traceback (most recent call last):
  File "C:\Users\Alex_SSHOR13\Competitions_TT\venv\Lib\site-packages\peewee.py", line 3322, in execute_sql
    cursor.execute(sql, params or ())
  File "C:\Users\Alex_SSHOR13\Competitions_TT\venv\Lib\site-packages\pymysql\cursors.py", line 153, in execute
    result = self._query(query)
             ^^^^^^^^^^^^^^^^^^
  File "C:\Users\Alex_SSHOR13\Competitions_TT\venv\Lib\site-packages\pymysql\cursors.py", line 322, in _query
    conn.query(q)
  File "C:\Users\Alex_SSHOR13\Competitions_TT\venv\Lib\site-packages\pymysql\connections.py", line 575, in query
    self._affected_rows = self._read_query_result(unbuffered=unbuffered)
                          ^^^^^^^^^^^^^^^^^^^^^^^^^^^^^^^^^^^^^^^^^^^^^^
  File "C:\Users\Alex_SSHOR13\Competitions_TT\venv\Lib\site-packages\pymysql\connections.py", line 826, in _read_query_result
    result.read()
  File "C:\Users\Alex_SSHOR13\Competitions_TT\venv\Lib\site-packages\pymysql\connections.py", line 1203, in read
    first_packet = self.connection._read_packet()
                   ^^^^^^^^^^^^^^^^^^^^^^^^^^^^^^
  File "C:\Users\Alex_SSHOR13\Competitions_TT\venv\Lib\site-packages\pymysql\connections.py", line 782, in _read_packet
    packet.raise_for_error()
  File "C:\Users\Alex_SSHOR13\Competitions_TT\venv\Lib\site-packages\pymysql\protocol.py", line 219, in raise_for_error
    err.raise_mysql_exception(self._data)
  File "C:\Users\Alex_SSHOR13\Competitions_TT\venv\Lib\site-packages\pymysql\err.py", line 150, in raise_mysql_exception
    raise errorclass(errno, errval)
pymysql.err.OperationalError: (1054, "Unknown column 't2.id' in 'where clause'")

During handling of the above exception, another exception occurred:

Traceback (most recent call last):
  File "c:\Users\Alex_SSHOR13\Competitions_TT\main.py", line 1389, in new
    db_r(gamer)
  File "c:\Users\Alex_SSHOR13\Competitions_TT\main.py", line 1616, in db_r
    system = System.get(Title.id == title)
             ^^^^^^^^^^^^^^^^^^^^^^^^^^^^^
  File "C:\Users\Alex_SSHOR13\Competitions_TT\venv\Lib\site-packages\peewee.py", line 6840, in get
    return sq.get()
           ^^^^^^^^
  File "C:\Users\Alex_SSHOR13\Competitions_TT\venv\Lib\site-packages\peewee.py", line 7297, in get
    return clone.execute(database)[0]
           ^^^^^^^^^^^^^^^^^^^^^^^
  File "C:\Users\Alex_SSHOR13\Competitions_TT\venv\Lib\site-packages\peewee.py", line 2036, in inner
    return method(self, database, *args, **kwargs)
           ^^^^^^^^^^^^^^^^^^^^^^^^^^^^^^^^^^^^^^^
  File "C:\Users\Alex_SSHOR13\Competitions_TT\venv\Lib\site-packages\peewee.py", line 2107, in execute
    return self._execute(database)
           ^^^^^^^^^^^^^^^^^^^^^^^
  File "C:\Users\Alex_SSHOR13\Competitions_TT\venv\Lib\site-packages\peewee.py", line 2280, in _execute
    cursor = database.execute(self)
             ^^^^^^^^^^^^^^^^^^^^^^
  File "C:\Users\Alex_SSHOR13\Competitions_TT\venv\Lib\site-packages\peewee.py", line 3330, in execute
    return self.execute_sql(sql, params)
           ^^^^^^^^^^^^^^^^^^^^^^^^^^^^^
  File "C:\Users\Alex_SSHOR13\Competitions_TT\venv\Lib\site-packages\peewee.py", line 3320, in execute_sql
    with __exception_wrapper__:
         ^^^^^^^^^^^^^^^^^^^^^
  File "C:\Users\Alex_SSHOR13\Competitions_TT\venv\Lib\site-packages\peewee.py", line 3088, in __exit__
    reraise(new_type, new_type(exc_value, *exc_args), traceback)
  File "C:\Users\Alex_SSHOR13\Competitions_TT\venv\Lib\site-packages\peewee.py", line 196, in reraise
    raise value.with_traceback(tb)
  File "C:\Users\Alex_SSHOR13\Competitions_TT\venv\Lib\site-packages\peewee.py", line 3322, in execute_sql
    cursor.execute(sql, params or ())
  File "C:\Users\Alex_SSHOR13\Competitions_TT\venv\Lib\site-packages\pymysql\cursors.py", line 153, in execute
    result = self._query(query)
             ^^^^^^^^^^^^^^^^^^
  File "C:\Users\Alex_SSHOR13\Competitions_TT\venv\Lib\site-packages\pymysql\cursors.py", line 322, in _query
    conn.query(q)
  File "C:\Users\Alex_SSHOR13\Competitions_TT\venv\Lib\site-packages\pymysql\connections.py", line 575, in query
    self._affected_rows = self._read_query_result(unbuffered=unbuffered)
                          ^^^^^^^^^^^^^^^^^^^^^^^^^^^^^^^^^^^^^^^^^^^^^^
  File "C:\Users\Alex_SSHOR13\Competitions_TT\venv\Lib\site-packages\pymysql\connections.py", line 826, in _read_query_result
    result.read()
  File "C:\Users\Alex_SSHOR13\Competitions_TT\venv\Lib\site-packages\pymysql\connections.py", line 1203, in read
    first_packet = self.connection._read_packet()
                   ^^^^^^^^^^^^^^^^^^^^^^^^^^^^^^
  File "C:\Users\Alex_SSHOR13\Competitions_TT\venv\Lib\site-packages\pymysql\connections.py", line 782, in _read_packet
    packet.raise_for_error()
  File "C:\Users\Alex_SSHOR13\Competitions_TT\venv\Lib\site-packages\pymysql\protocol.py", line 219, in raise_for_error
    err.raise_mysql_exception(self._data)
  File "C:\Users\Alex_SSHOR13\Competitions_TT\venv\Lib\site-packages\pymysql\err.py", line 150, in raise_mysql_exception
    raise errorclass(errno, errval)
peewee.OperationalError: (1054, "Unknown column 't2.id' in 'where clause'")
